Workbook

Sheet README
A1: IPOA Financial Plan — How to Read This Model
A2: Solana Frontier Hackathon 2026 · April 2026
A4: Sheet map
A5: Summary | B5: Top-of-funnel view: revenue, EBITDA, AUM across all 3 scenarios, plus Y5 base-case tiles.
A6: Assumptions | B6: Every blue cell is an input. Change them to stress-test. Conservative / Base / Aggressive live side-by-side.
A7: Revenue | B7: Builds AUM roll-forward and four revenue streams (origination, servicing, secondary, analytics) for each scenario.
A8: Costs | B8: Personnel (headcount × FL cost) + infra + G&A as % of revenue.
A9: P&L | B9: Revenue − costs = EBITDA, with margin % and cumulative burn/profit.
A10: KPIs | B10: Catalogs listed, AUM, recurring revenue, take rate.
A12: Color legend
A13: Blue | B13: Hardcoded input — change to stress the model
A14: Black | B14: Calculation (formula)
A15: Green | B15: Cross-sheet reference (pulls from another tab)
A16: Yellow fill | B16: Key assumption worth flagging
A18: Revenue model
A19: Origination | B19: 2.5% of listing $ at catalog mint (base case). Paid once per new listing.
A20: Servicing | B20: 0.75% of average AUM per year. Skimmed off royalty payouts flowing through on-chain vaults.
A21: Secondary market | B21: 0.25% of secondary trading volume (base); volume modeled as a % of AUM.
A22: Analytics | B22: Institutional subscribers × ARPU/month × 12. The Bloomberg/MSCI analog for the asset class.
A24: Note on conservatism
A25: Base case assumes ~100% catalog growth YoY in Y2, tapering to 75% by Y5 — modest for a marketplace with PRO data moat. Conservative assumes growth stalls at regulatory/funding friction. Aggressive assumes a label partnership or aggregator deal lands by Y2.

Sheet Summary
A1: IPOA — Financial Plan Model
A2: 5-year projection · three scenarios · April 2026
A4: Headline P&L by scenario
A5: Revenue / scenario | B5: 2026 | C5: 2027 | D5: 2028 | E5: 2029 | F5: 2030 | G5: 5-yr total
A6: Conservative | B6: =Revenue!C20 -> 23265 | C6: =Revenue!D20 -> 68410.125 | D6: =Revenue!E20 -> 191778.15 | E6: =Revenue!F20 -> 448901.63 | F6: =Revenue!G20 -> 887398.07 | G6: =SUM(B6:F6) -> 1619753
A7: Base | B7: =Revenue!C36 -> 432500 | C7: =Revenue!D36 -> 990796.88 | D7: =Revenue!E36 -> 2493124.2 | E7: =Revenue!F36 -> 5802827 | F7: =Revenue!G36 -> 12781042 | G7: =SUM(B7:F7) -> 22500290
A8: Aggressive | B8: =Revenue!C52 -> 2145600 | C8: =Revenue!D52 -> 6091488 | D8: =Revenue!E52 -> 18631227 | E8: =Revenue!F52 -> 52670954 | F8: =Revenue!G52 -> 1.3009237e+08 | G8: =SUM(B8:F8) -> 2.0963164e+08
A10: EBITDA / scenario | B10: 2026 | C10: 2027 | D10: 2028 | E10: 2029 | F10: 2030 | G10: 5-yr total
A11: Conservative | B11: ='P&L'!C9 -> -579526.8 | C11: ='P&L'!D9 -> -914799.09 | D11: ='P&L'!E9 -> -1386235.2 | E11: ='P&L'!F9 -> -1957966.6 | F11: ='P&L'!G9 -> -2609089.7 | G11: =SUM(B11:F11) -> -7447617.4
A12: Base | B12: ='P&L'!C16 -> -502375 | C12: ='P&L'!D16 -> -847822.66 | D12: ='P&L'!E16 -> -834844.41 | E12: ='P&L'!F16 -> 230402.94 | F12: ='P&L'!G16 -> 3887885.9 | G12: =SUM(B12:F12) -> 1933246.8
A13: Aggressive | B13: ='P&L'!C23 -> 359392 | C13: ='P&L'!D23 -> 1735020.2 | D13: ='P&L'!E23 -> 8605606 | E13: ='P&L'!F23 -> 31330183 | F13: ='P&L'!G23 -> 87363747 | G13: =SUM(B13:F13) -> 1.2939395e+08
A15: AUM, end of year | B15: 2026 | C15: 2027 | D15: 2028 | E15: 2029 | F15: 2030
A16: Conservative | B16: =Revenue!C13 -> 300000 | C16: =Revenue!D13 -> 1335000 | D16: =Revenue!E13 -> 4302750 | E16: =Revenue!F13 -> 11260538 | F16: =Revenue!G13 -> 24086657
A17: Base | B17: =Revenue!C29 -> 2500000 | C17: =Revenue!D29 -> 10875000 | D17: =Revenue!E29 -> 34584375 | E17: =Revenue!F29 -> 88158938 | F17: =Revenue!G29 -> 1.9416621e+08
A18: Aggressive | B18: =Revenue!C45 -> 9600000 | C18: =Revenue!D45 -> 49152000 | D18: =Revenue!E45 -> 190371840 | E18: =Revenue!F45 -> 6.1059809e+08 | F18: =Revenue!G45 -> 1.6068446e+09
A20: Base case at year 5
A21: Revenue | C21: EBITDA | E21: AUM (EOY) | G21: Cumulative catalogs
A22: =Revenue!G36 -> 12781042 | C22: ='P&L'!G16 -> 3887885.9 | E22: =Revenue!G29 -> 1.9416621e+08 | G22: =Revenue!G24 -> 2638
A24: Break-even in Y4 under base case. Servicing on AUM becomes the dominant recurring line by Y5, giving the business a Moody's-style annuity tail once the rating franchise is established.

Sheet Assumptions
A1: Assumptions
A2: All blue cells are direct inputs. Change them to stress-test the model.
C4: Conservative | I4: Base | O4: Aggressive
A5: Driver | B5: Unit | C5: 2026 | D5: 2027 | E5: 2028 | F5: 2029 | G5: 2030 | I5: 2026 | J5: 2027 | K5: 2028 | L5: 2029 | M5: 2030 | O5: 2026 | P5: 2027 | Q5: 2028 | R5: 2029 | S5: 2030
A6: MARKET ACTIVITY
A7: New catalogs listed | B7: count | C7: 15 | D7: 45 | E7: 110 | F7: 220 | G7: 350 | I7: 50 | J7: 150 | K7: 375 | L7: 750 | M7: 1313 | O7: 120 | P7: 420 | Q7: 1260 | R7: 3150 | S7: 6300
A8: Avg catalog listing value | B8: $ | C8: 20000 | D8: 24000 | E8: 28800 | F8: 34560 | G8: 41472 | I8: 50000 | J8: 57500 | K8: 66125 | L8: 76044 | M8: 87451 | O8: 80000 | P8: 96000 | Q8: 115200 | R8: 138240 | S8: 165888
A9: AUM runoff rate | B9: % per yr | C9: 0.15 | D9: 0.15 | E9: 0.15 | F9: 0.15 | G9: 0.15 | I9: 0.1 | J9: 0.1 | K9: 0.1 | L9: 0.1 | M9: 0.1 | O9: 0.08 | P9: 0.08 | Q9: 0.08 | R9: 0.08 | S9: 0.08
A10: TRANSACTION FEES
A11: Origination fee rate | B11: % of listing | C11: 0.015 | D11: 0.015 | E11: 0.015 | F11: 0.015 | G11: 0.015 | I11: 0.025 | J11: 0.025 | K11: 0.025 | L11: 0.025 | M11: 0.025 | O11: 0.03 | P11: 0.03 | Q11: 0.03 | R11: 0.03 | S11: 0.03
A12: Servicing fee rate | B12: % of avg AUM | C12: 0.005 | D12: 0.005 | E12: 0.005 | F12: 0.005 | G12: 0.005 | I12: 0.0075 | J12: 0.0075 | K12: 0.0075 | L12: 0.0075 | M12: 0.0075 | O12: 0.01 | P12: 0.01 | Q12: 0.01 | R12: 0.01 | S12: 0.01
A13: Secondary volume | B13: % of avg AUM | C13: 0.1 | D13: 0.15 | E13: 0.2 | F13: 0.25 | G13: 0.3 | I13: 0.2 | J13: 0.3 | K13: 0.4 | L13: 0.5 | M13: 0.6 | O13: 0.4 | P13: 0.6 | Q13: 0.8 | R13: 1 | S13: 1.2
A14: Secondary market fee | B14: % of volume | C14: 0.001 | D14: 0.001 | E14: 0.001 | F14: 0.001 | G14: 0.001 | I14: 0.0025 | J14: 0.0025 | K14: 0.0025 | L14: 0.0025 | M14: 0.0025 | O14: 0.005 | P14: 0.005 | Q14: 0.005 | R14: 0.005 | S14: 0.005
A15: ANALYTICS SUBSCRIPTIONS
A16: Institutional subscribers | B16: count | C16: 3 | D16: 8 | E16: 18 | F16: 35 | G16: 60 | I16: 20 | J16: 40 | K16: 80 | L16: 160 | M16: 320 | O16: 50 | P16: 125 | Q16: 300 | R16: 700 | S16: 1500
A17: Subscription ARPU | B17: $/mo | C17: 500 | D17: 500 | E17: 600 | F17: 700 | G17: 800 | I17: 1500 | J17: 1500 | K17: 1750 | L17: 2000 | M17: 2250 | O17: 3000 | P17: 3000 | Q17: 3500 | R17: 4000 | S17: 4500
A18: OPERATING COSTS
A19: Headcount (avg) | B19: FTE | C19: 3 | D19: 5 | E19: 8 | F19: 12 | G19: 17 | I19: 4 | J19: 8 | K19: 14 | L19: 22 | M19: 32 | O19: 6 | P19: 14 | Q19: 28 | R19: 48 | S19: 75
A20: Fully-loaded cost / head | B20: $/yr | C20: 160000 | D20: 165000 | E20: 170000 | F20: 175000 | G20: 180000 | I20: 180000 | J20: 185000 | K20: 190000 | L20: 195000 | M20: 200000 | O20: 200000 | P20: 210000 | Q20: 220000 | R20: 230000 | S20: 240000
A21: Infra + compliance | B21: $/yr | C21: 120000 | D21: 150000 | E21: 195000 | F21: 253000 | G21: 330000 | I21: 150000 | J21: 210000 | K21: 294000 | L21: 412000 | M21: 576000 | O21: 200000 | P21: 320000 | Q21: 512000 | R21: 820000 | S21: 1312000
A22: G&A + marketing | B22: % of revenue | C22: 0.12 | D22: 0.12 | E22: 0.12 | F22: 0.12 | G22: 0.12 | I22: 0.15 | J22: 0.15 | K22: 0.15 | L22: 0.15 | M22: 0.15 | O22: 0.18 | P22: 0.18 | Q22: 0.18 | R22: 0.18 | S22: 0.18

Sheet Revenue
A1: Revenue Build
A2: Revenue = Origination + Servicing + Secondary market + Analytics subscriptions.
A4: Line | B4: Unit | C4: 2026 | D4: 2027 | E4: 2028 | F4: 2029 | G4: 2030
A6: Conservative
A7: New catalogs listed | B7: count | C7: =Assumptions!C7 -> 15 | D7: =Assumptions!D7 -> 45 | E7: =Assumptions!E7 -> 110 | F7: =Assumptions!F7 -> 220 | G7: =Assumptions!G7 -> 350
A8: Cumulative catalogs | B8: count | C8: =C7 -> 15 | D8: =C8+D7 -> 60 | E8: =D8+E7 -> 170 | F8: =E8+F7 -> 390 | G8: =F8+G7 -> 740
A9: Avg catalog listing value | B9: $ | C9: =Assumptions!C8 -> 20000 | D9: =Assumptions!D8 -> 24000 | E9: =Assumptions!E8 -> 28800 | F9: =Assumptions!F8 -> 34560 | G9: =Assumptions!G8 -> 41472
A10: New listings value | B10: $ | C10: =C7*C9 -> 300000 | D10: =D7*D9 -> 1080000 | E10: =E7*E9 -> 3168000 | F10: =F7*F9 -> 7603200 | G10: =G7*G9 -> 14515200
A11: AUM runoff rate | B11: % | C11: =Assumptions!C9 -> 0.15 | D11: =Assumptions!D9 -> 0.15 | E11: =Assumptions!E9 -> 0.15 | F11: =Assumptions!F9 -> 0.15 | G11: =Assumptions!G9 -> 0.15
A12: AUM — BOY | B12: $ | C12: =0 -> 0 | D12: =C13 -> 300000 | E12: =D13 -> 1335000 | F12: =E13 -> 4302750 | G12: =F13 -> 11260538
A13: AUM — EOY | B13: $ | C13: =C12*(1-C11)+C10 -> 300000 | D13: =D12*(1-D11)+D10 -> 1335000 | E13: =E12*(1-E11)+E10 -> 4302750 | F13: =F12*(1-F11)+F10 -> 11260538 | G13: =G12*(1-G11)+G10 -> 24086657
A14: AUM — average | B14: $ | C14: =AVERAGE(C12,C13) -> 150000 | D14: =AVERAGE(D12,D13) -> 817500 | E14: =AVERAGE(E12,E13) -> 2818875 | F14: =AVERAGE(F12,F13) -> 7781643.8 | G14: =AVERAGE(G12,G13) -> 17673597
A16: Origination fees | B16: $ | C16: =C10*Assumptions!C11 -> 4500 | D16: =D10*Assumptions!D11 -> 16200 | E16: =E10*Assumptions!E11 -> 47520 | F16: =F10*Assumptions!F11 -> 114048 | G16: =G10*Assumptions!G11 -> 217728
A17: Servicing fees (on AUM) | B17: $ | C17: =C14*Assumptions!C12 -> 750 | D17: =D14*Assumptions!D12 -> 4087.5 | E17: =E14*Assumptions!E12 -> 14094.375 | F17: =F14*Assumptions!F12 -> 38908.219 | G17: =G14*Assumptions!G12 -> 88367.986
A18: Secondary market fees | B18: $ | C18: =C14*Assumptions!C13*Assumptions!C14 -> 15 | D18: =D14*Assumptions!D13*Assumptions!D14 -> 122.625 | E18: =E14*Assumptions!E13*Assumptions!E14 -> 563.775 | F18: =F14*Assumptions!F13*Assumptions!F14 -> 1945.4109 | G18: =G14*Assumptions!G13*Assumptions!G14 -> 5302.0792
A19: Analytics subscriptions | B19: $ | C19: =Assumptions!C16*Assumptions!C17*12 -> 18000 | D19: =Assumptions!D16*Assumptions!D17*12 -> 48000 | E19: =Assumptions!E16*Assumptions!E17*12 -> 129600 | F19: =Assumptions!F16*Assumptions!F17*12 -> 294000 | G19: =Assumptions!G16*Assumptions!G17*12 -> 576000
A20: Total revenue | B20: $ | C20: =SUM(C16:C19) -> 23265 | D20: =SUM(D16:D19) -> 68410.125 | E20: =SUM(E16:E19) -> 191778.15 | F20: =SUM(F16:F19) -> 448901.63 | G20: =SUM(G16:G19) -> 887398.07
A22: Base
A23: New catalogs listed | B23: count | C23: =Assumptions!I7 -> 50 | D23: =Assumptions!J7 -> 150 | E23: =Assumptions!K7 -> 375 | F23: =Assumptions!L7 -> 750 | G23: =Assumptions!M7 -> 1313
A24: Cumulative catalogs | B24: count | C24: =C23 -> 50 | D24: =C24+D23 -> 200 | E24: =D24+E23 -> 575 | F24: =E24+F23 -> 1325 | G24: =F24+G23 -> 2638
A25: Avg catalog listing value | B25: $ | C25: =Assumptions!I8 -> 50000 | D25: =Assumptions!J8 -> 57500 | E25: =Assumptions!K8 -> 66125 | F25: =Assumptions!L8 -> 76044 | G25: =Assumptions!M8 -> 87451
A26: New listings value | B26: $ | C26: =C23*C25 -> 2500000 | D26: =D23*D25 -> 8625000 | E26: =E23*E25 -> 24796875 | F26: =F23*F25 -> 57033000 | G26: =G23*G25 -> 114823163
A27: AUM runoff rate | B27: % | C27: =Assumptions!I9 -> 0.1 | D27: =Assumptions!J9 -> 0.1 | E27: =Assumptions!K9 -> 0.1 | F27: =Assumptions!L9 -> 0.1 | G27: =Assumptions!M9 -> 0.1
A28: AUM — BOY | B28: $ | C28: =0 -> 0 | D28: =C29 -> 2500000 | E28: =D29 -> 10875000 | F28: =E29 -> 34584375 | G28: =F29 -> 88158938
A29: AUM — EOY | B29: $ | C29: =C28*(1-C27)+C26 -> 2500000 | D29: =D28*(1-D27)+D26 -> 10875000 | E29: =E28*(1-E27)+E26 -> 34584375 | F29: =F28*(1-F27)+F26 -> 88158938 | G29: =G28*(1-G27)+G26 -> 1.9416621e+08
A30: AUM — average | B30: $ | C30: =AVERAGE(C28,C29) -> 1250000 | D30: =AVERAGE(D28,D29) -> 6687500 | E30: =AVERAGE(E28,E29) -> 22729688 | F30: =AVERAGE(F28,F29) -> 61371656 | G30: =AVERAGE(G28,G29) -> 1.4116257e+08
A32: Origination fees | B32: $ | C32: =C26*Assumptions!I11 -> 62500 | D32: =D26*Assumptions!J11 -> 215625 | E32: =E26*Assumptions!K11 -> 619921.88 | F32: =F26*Assumptions!L11 -> 1425825 | G32: =G26*Assumptions!M11 -> 2870579.1
A33: Servicing fees (on AUM) | B33: $ | C33: =C30*Assumptions!I12 -> 9375 | D33: =D30*Assumptions!J12 -> 50156.25 | E33: =E30*Assumptions!K12 -> 170472.66 | F33: =F30*Assumptions!L12 -> 460287.42 | G33: =G30*Assumptions!M12 -> 1058719.3
A34: Secondary market fees | B34: $ | C34: =C30*Assumptions!I13*Assumptions!I14 -> 625 | D34: =D30*Assumptions!J13*Assumptions!J14 -> 5015.625 | E34: =E30*Assumptions!K13*Assumptions!K14 -> 22729.688 | F34: =F30*Assumptions!L13*Assumptions!L14 -> 76714.57 | G34: =G30*Assumptions!M13*Assumptions!M14 -> 211743.86
A35: Analytics subscriptions | B35: $ | C35: =Assumptions!I16*Assumptions!I17*12 -> 360000 | D35: =Assumptions!J16*Assumptions!J17*12 -> 720000 | E35: =Assumptions!K16*Assumptions!K17*12 -> 1680000 | F35: =Assumptions!L16*Assumptions!L17*12 -> 3840000 | G35: =Assumptions!M16*Assumptions!M17*12 -> 8640000
A36: Total revenue | B36: $ | C36: =SUM(C32:C35) -> 432500 | D36: =SUM(D32:D35) -> 990796.88 | E36: =SUM(E32:E35) -> 2493124.2 | F36: =SUM(F32:F35) -> 5802827 | G36: =SUM(G32:G35) -> 12781042
A38: Aggressive
A39: New catalogs listed | B39: count | C39: =Assumptions!O7 -> 120 | D39: =Assumptions!P7 -> 420 | E39: =Assumptions!Q7 -> 1260 | F39: =Assumptions!R7 -> 3150 | G39: =Assumptions!S7 -> 6300
A40: Cumulative catalogs | B40: count | C40: =C39 -> 120 | D40: =C40+D39 -> 540 | E40: =D40+E39 -> 1800 | F40: =E40+F39 -> 4950 | G40: =F40+G39 -> 11250
A41: Avg catalog listing value | B41: $ | C41: =Assumptions!O8 -> 80000 | D41: =Assumptions!P8 -> 96000 | E41: =Assumptions!Q8 -> 115200 | F41: =Assumptions!R8 -> 138240 | G41: =Assumptions!S8 -> 165888
A42: New listings value | B42: $ | C42: =C39*C41 -> 9600000 | D42: =D39*D41 -> 40320000 | E42: =E39*E41 -> 145152000 | F42: =F39*F41 -> 435456000 | G42: =G39*G41 -> 1045094400
A43: AUM runoff rate | B43: % | C43: =Assumptions!O9 -> 0.08 | D43: =Assumptions!P9 -> 0.08 | E43: =Assumptions!Q9 -> 0.08 | F43: =Assumptions!R9 -> 0.08 | G43: =Assumptions!S9 -> 0.08
A44: AUM — BOY | B44: $ | C44: =0 -> 0 | D44: =C45 -> 9600000 | E44: =D45 -> 49152000 | F44: =E45 -> 190371840 | G44: =F45 -> 6.1059809e+08
A45: AUM — EOY | B45: $ | C45: =C44*(1-C43)+C42 -> 9600000 | D45: =D44*(1-D43)+D42 -> 49152000 | E45: =E44*(1-E43)+E42 -> 190371840 | F45: =F44*(1-F43)+F42 -> 6.1059809e+08 | G45: =G44*(1-G43)+G42 -> 1.6068446e+09
A46: AUM — average | B46: $ | C46: =AVERAGE(C44,C45) -> 4800000 | D46: =AVERAGE(D44,D45) -> 29376000 | E46: =AVERAGE(E44,E45) -> 119761920 | F46: =AVERAGE(F44,F45) -> 4.0048497e+08 | G46: =AVERAGE(G44,G45) -> 1.1087214e+09
...

Sheet Costs
A1: Operating Costs
A2: Team comp is the largest line; infra + G&A scale with revenue.
A4: Line | B4: Unit | C4: 2026 | D4: 2027 | E4: 2028 | F4: 2029 | G4: 2030
A6: Conservative
A7: Headcount (avg) | B7: FTE | C7: =Assumptions!C19 -> 3 | D7: =Assumptions!D19 -> 5 | E7: =Assumptions!E19 -> 8 | F7: =Assumptions!F19 -> 12 | G7: =Assumptions!G19 -> 17
A8: Fully-loaded cost / head | B8: $/yr | C8: =Assumptions!C20 -> 160000 | D8: =Assumptions!D20 -> 165000 | E8: =Assumptions!E20 -> 170000 | F8: =Assumptions!F20 -> 175000 | G8: =Assumptions!G20 -> 180000
A9: Personnel | B9: $ | C9: =C7*C8 -> 480000 | D9: =D7*D8 -> 825000 | E9: =E7*E8 -> 1360000 | F9: =F7*F8 -> 2100000 | G9: =G7*G8 -> 3060000
A10: Infra + compliance | B10: $ | C10: =Assumptions!C21 -> 120000 | D10: =Assumptions!D21 -> 150000 | E10: =Assumptions!E21 -> 195000 | F10: =Assumptions!F21 -> 253000 | G10: =Assumptions!G21 -> 330000
A11: G&A + marketing | B11: $ | C11: =Revenue!C20*Assumptions!C22 -> 2791.8 | D11: =Revenue!D20*Assumptions!D22 -> 8209.215 | E11: =Revenue!E20*Assumptions!E22 -> 23013.378 | F11: =Revenue!F20*Assumptions!F22 -> 53868.196 | G11: =Revenue!G20*Assumptions!G22 -> 106487.77
A12: Total operating costs | B12: $ | C12: =C9+C10+C11 -> 602791.8 | D12: =D9+D10+D11 -> 983209.21 | E12: =E9+E10+E11 -> 1578013.4 | F12: =F9+F10+F11 -> 2406868.2 | G12: =G9+G10+G11 -> 3496487.8
A14: Base
A15: Headcount (avg) | B15: FTE | C15: =Assumptions!I19 -> 4 | D15: =Assumptions!J19 -> 8 | E15: =Assumptions!K19 -> 14 | F15: =Assumptions!L19 -> 22 | G15: =Assumptions!M19 -> 32
A16: Fully-loaded cost / head | B16: $/yr | C16: =Assumptions!I20 -> 180000 | D16: =Assumptions!J20 -> 185000 | E16: =Assumptions!K20 -> 190000 | F16: =Assumptions!L20 -> 195000 | G16: =Assumptions!M20 -> 200000
A17: Personnel | B17: $ | C17: =C15*C16 -> 720000 | D17: =D15*D16 -> 1480000 | E17: =E15*E16 -> 2660000 | F17: =F15*F16 -> 4290000 | G17: =G15*G16 -> 6400000
A18: Infra + compliance | B18: $ | C18: =Assumptions!I21 -> 150000 | D18: =Assumptions!J21 -> 210000 | E18: =Assumptions!K21 -> 294000 | F18: =Assumptions!L21 -> 412000 | G18: =Assumptions!M21 -> 576000
A19: G&A + marketing | B19: $ | C19: =Revenue!C36*Assumptions!I22 -> 64875 | D19: =Revenue!D36*Assumptions!J22 -> 148619.53 | E19: =Revenue!E36*Assumptions!K22 -> 373968.63 | F19: =Revenue!F36*Assumptions!L22 -> 870424.05 | G19: =Revenue!G36*Assumptions!M22 -> 1917156.3
A20: Total operating costs | B20: $ | C20: =C17+C18+C19 -> 934875 | D20: =D17+D18+D19 -> 1838619.5 | E20: =E17+E18+E19 -> 3327968.6 | F20: =F17+F18+F19 -> 5572424 | G20: =G17+G18+G19 -> 8893156.3
A22: Aggressive
A23: Headcount (avg) | B23: FTE | C23: =Assumptions!O19 -> 6 | D23: =Assumptions!P19 -> 14 | E23: =Assumptions!Q19 -> 28 | F23: =Assumptions!R19 -> 48 | G23: =Assumptions!S19 -> 75
A24: Fully-loaded cost / head | B24: $/yr | C24: =Assumptions!O20 -> 200000 | D24: =Assumptions!P20 -> 210000 | E24: =Assumptions!Q20 -> 220000 | F24: =Assumptions!R20 -> 230000 | G24: =Assumptions!S20 -> 240000
A25: Personnel | B25: $ | C25: =C23*C24 -> 1200000 | D25: =D23*D24 -> 2940000 | E25: =E23*E24 -> 6160000 | F25: =F23*F24 -> 11040000 | G25: =G23*G24 -> 18000000
A26: Infra + compliance | B26: $ | C26: =Assumptions!O21 -> 200000 | D26: =Assumptions!P21 -> 320000 | E26: =Assumptions!Q21 -> 512000 | F26: =Assumptions!R21 -> 820000 | G26: =Assumptions!S21 -> 1312000
A27: G&A + marketing | B27: $ | C27: =Revenue!C52*Assumptions!O22 -> 386208 | D27: =Revenue!D52*Assumptions!P22 -> 1096467.8 | E27: =Revenue!E52*Assumptions!Q22 -> 3353620.8 | F27: =Revenue!F52*Assumptions!R22 -> 9480771.8 | G27: =Revenue!G52*Assumptions!S22 -> 23416627
A28: Total operating costs | B28: $ | C28: =C25+C26+C27 -> 1786208 | D28: =D25+D26+D27 -> 4356467.8 | E28: =E25+E26+E27 -> 10025621 | F28: =F25+F26+F27 -> 21340772 | G28: =G25+G26+G27 -> 42728627

Sheet P&L
A1: Profit & Loss
A2: Revenue, costs, EBITDA, margin by year and scenario.
A4: Line | B4: Unit | C4: 2026 | D4: 2027 | E4: 2028 | F4: 2029 | G4: 2030
A6: Conservative
A7: Revenue | B7: $ | C7: =Revenue!C20 -> 23265 | D7: =Revenue!D20 -> 68410.125 | E7: =Revenue!E20 -> 191778.15 | F7: =Revenue!F20 -> 448901.63 | G7: =Revenue!G20 -> 887398.07
A8: (−) Operating costs | B8: $ | C8: =-Costs!C12 -> -602791.8 | D8: =-Costs!D12 -> -983209.21 | E8: =-Costs!E12 -> -1578013.4 | F8: =-Costs!F12 -> -2406868.2 | G8: =-Costs!G12 -> -3496487.8
A9: EBITDA | B9: $ | C9: =C7+C8 -> -579526.8 | D9: =D7+D8 -> -914799.09 | E9: =E7+E8 -> -1386235.2 | F9: =F7+F8 -> -1957966.6 | G9: =G7+G8 -> -2609089.7
A10: EBITDA margin | B10: % | C10: =IF(C7=0,0,C9/C7) -> -24.909813 | D10: =IF(D7=0,0,D9/D7) -> -13.372276 | E10: =IF(E7=0,0,E9/E7) -> -7.2283273 | F10: =IF(F7=0,0,F9/F7) -> -4.3616829 | G10: =IF(G7=0,0,G9/G7) -> -2.9401571
A11: Cumulative EBITDA (capital need) | B11: $ | C11: =C9 -> -579526.8 | D11: =C11+D9 -> -1494325.9 | E11: =D11+E9 -> -2880561.1 | F11: =E11+F9 -> -4838527.7 | G11: =F11+G9 -> -7447617.4
A13: Base
A14: Revenue | B14: $ | C14: =Revenue!C36 -> 432500 | D14: =Revenue!D36 -> 990796.88 | E14: =Revenue!E36 -> 2493124.2 | F14: =Revenue!F36 -> 5802827 | G14: =Revenue!G36 -> 12781042
A15: (−) Operating costs | B15: $ | C15: =-Costs!C20 -> -934875 | D15: =-Costs!D20 -> -1838619.5 | E15: =-Costs!E20 -> -3327968.6 | F15: =-Costs!F20 -> -5572424 | G15: =-Costs!G20 -> -8893156.3
A16: EBITDA | B16: $ | C16: =C14+C15 -> -502375 | D16: =D14+D15 -> -847822.66 | E16: =E14+E15 -> -834844.41 | F16: =F14+F15 -> 230402.94 | G16: =G14+G15 -> 3887885.9
A17: EBITDA margin | B17: % | C17: =IF(C14=0,0,C16/C14) -> -1.1615607 | D17: =IF(D14=0,0,D16/D14) -> -0.85569775 | E17: =IF(E14=0,0,E16/E14) -> -0.33485873 | F17: =IF(F14=0,0,F16/F14) -> 0.039705293 | G17: =IF(G14=0,0,G16/G14) -> 0.30419162
A18: Cumulative EBITDA (capital need) | B18: $ | C18: =C16 -> -502375 | D18: =C18+D16 -> -1350197.7 | E18: =D18+E16 -> -2185042.1 | F18: =E18+F16 -> -1954639.1 | G18: =F18+G16 -> 1933246.8
A20: Aggressive
A21: Revenue | B21: $ | C21: =Revenue!C52 -> 2145600 | D21: =Revenue!D52 -> 6091488 | E21: =Revenue!E52 -> 18631227 | F21: =Revenue!F52 -> 52670954 | G21: =Revenue!G52 -> 1.3009237e+08
A22: (−) Operating costs | B22: $ | C22: =-Costs!C28 -> -1786208 | D22: =-Costs!D28 -> -4356467.8 | E22: =-Costs!E28 -> -10025621 | F22: =-Costs!F28 -> -21340772 | G22: =-Costs!G28 -> -42728627
A23: EBITDA | B23: $ | C23: =C21+C22 -> 359392 | D23: =D21+D22 -> 1735020.2 | E23: =E21+E22 -> 8605606 | F23: =F21+F22 -> 31330183 | G23: =G21+G22 -> 87363747
A24: EBITDA margin | B24: % | C24: =IF(C21=0,0,C23/C21) -> 0.16750186 | D24: =IF(D21=0,0,D23/D21) -> 0.28482698 | E24: =IF(E21=0,0,E23/E21) -> 0.46189154 | F24: =IF(F21=0,0,F23/F21) -> 0.59482846 | G24: =IF(G21=0,0,G23/G21) -> 0.67155164
A25: Cumulative EBITDA (capital need) | B25: $ | C25: =C23 -> 359392 | D25: =C25+D23 -> 2094412.2 | E25: =D25+E23 -> 10700018 | F25: =E25+F23 -> 42030201 | G25: =F25+G23 -> 1.2939395e+08

Sheet KPIs
A1: Key Performance Indicators
A2: Operating metrics judges and investors care about.
A4: Metric | B4: Unit | C4: 2026 | D4: 2027 | E4: 2028 | F4: 2029 | G4: 2030
A6: Conservative
A7: Cumulative catalogs listed | B7: count | C7: =Revenue!C8 -> 15 | D7: =Revenue!D8 -> 60 | E7: =Revenue!E8 -> 170 | F7: =Revenue!F8 -> 390 | G7: =Revenue!G8 -> 740
A8: AUM (EOY) | B8: $ | C8: =Revenue!C13 -> 300000 | D8: =Revenue!D13 -> 1335000 | E8: =Revenue!E13 -> 4302750 | F8: =Revenue!F13 -> 11260538 | G8: =Revenue!G13 -> 24086657
A9: Recurring revenue (servicing + analytics) | B9: $ | C9: =Revenue!C17+Revenue!C19 -> 18750 | D9: =Revenue!D17+Revenue!D19 -> 52087.5 | E9: =Revenue!E17+Revenue!E19 -> 143694.38 | F9: =Revenue!F17+Revenue!F19 -> 332908.22 | G9: =Revenue!G17+Revenue!G19 -> 664367.99
A10: Revenue per cumulative catalog | B10: $ | C10: =IF(Revenue!C8=0,0,Revenue!C20/Revenue!C8) -> 1551 | D10: =IF(Revenue!D8=0,0,Revenue!D20/Revenue!D8) -> 1140.1688 | E10: =IF(Revenue!E8=0,0,Revenue!E20/Revenue!E8) -> 1128.1068 | F10: =IF(Revenue!F8=0,0,Revenue!F20/Revenue!F8) -> 1151.0298 | G10: =IF(Revenue!G8=0,0,Revenue!G20/Revenue!G8) -> 1199.1866
A11: Effective take rate (rev / new listings $) | B11: % | C11: =IF(Revenue!C10=0,0,Revenue!C20/Revenue!C10) -> 0.07755 | D11: =IF(Revenue!D10=0,0,Revenue!D20/Revenue!D10) -> 0.063342708 | E11: =IF(Revenue!E10=0,0,Revenue!E20/Revenue!E10) -> 0.060536032 | F11: =IF(Revenue!F10=0,0,Revenue!F20/Revenue!F10) -> 0.059041144 | G11: =IF(Revenue!G10=0,0,Revenue!G20/Revenue!G10) -> 0.061135779
A13: Base
A14: Cumulative catalogs listed | B14: count | C14: =Revenue!C24 -> 50 | D14: =Revenue!D24 -> 200 | E14: =Revenue!E24 -> 575 | F14: =Revenue!F24 -> 1325 | G14: =Revenue!G24 -> 2638
A15: AUM (EOY) | B15: $ | C15: =Revenue!C29 -> 2500000 | D15: =Revenue!D29 -> 10875000 | E15: =Revenue!E29 -> 34584375 | F15: =Revenue!F29 -> 88158938 | G15: =Revenue!G29 -> 1.9416621e+08
A16: Recurring revenue (servicing + analytics) | B16: $ | C16: =Revenue!C33+Revenue!C35 -> 369375 | D16: =Revenue!D33+Revenue!D35 -> 770156.25 | E16: =Revenue!E33+Revenue!E35 -> 1850472.7 | F16: =Revenue!F33+Revenue!F35 -> 4300287.4 | G16: =Revenue!G33+Revenue!G35 -> 9698719.3
A17: Revenue per cumulative catalog | B17: $ | C17: =IF(Revenue!C24=0,0,Revenue!C36/Revenue!C24) -> 8650 | D17: =IF(Revenue!D24=0,0,Revenue!D36/Revenue!D24) -> 4953.9844 | E17: =IF(Revenue!E24=0,0,Revenue!E36/Revenue!E24) -> 4335.8682 | F17: =IF(Revenue!F24=0,0,Revenue!F36/Revenue!F24) -> 4379.4921 | G17: =IF(Revenue!G24=0,0,Revenue!G36/Revenue!G24) -> 4844.9743
A18: Effective take rate (rev / new listings $) | B18: % | C18: =IF(Revenue!C26=0,0,Revenue!C36/Revenue!C26) -> 0.173 | D18: =IF(Revenue!D26=0,0,Revenue!D36/Revenue!D26) -> 0.114875 | E18: =IF(Revenue!E26=0,0,Revenue!E36/Revenue!E26) -> 0.10054187 | F18: =IF(Revenue!F26=0,0,Revenue!F36/Revenue!F26) -> 0.10174508 | G18: =IF(Revenue!G26=0,0,Revenue!G36/Revenue!G26) -> 0.11131066
A20: Aggressive
A21: Cumulative catalogs listed | B21: count | C21: =Revenue!C40 -> 120 | D21: =Revenue!D40 -> 540 | E21: =Revenue!E40 -> 1800 | F21: =Revenue!F40 -> 4950 | G21: =Revenue!G40 -> 11250
A22: AUM (EOY) | B22: $ | C22: =Revenue!C45 -> 9600000 | D22: =Revenue!D45 -> 49152000 | E22: =Revenue!E45 -> 190371840 | F22: =Revenue!F45 -> 6.1059809e+08 | G22: =Revenue!G45 -> 1.6068446e+09
A23: Recurring revenue (servicing + analytics) | B23: $ | C23: =Revenue!C49+Revenue!C51 -> 1848000 | D23: =Revenue!D49+Revenue!D51 -> 4793760 | E23: =Revenue!E49+Revenue!E51 -> 13797619 | F23: =Revenue!F49+Revenue!F51 -> 37604850 | G23: =Revenue!G49+Revenue!G51 -> 92087214
A24: Revenue per cumulative catalog | B24: $ | C24: =IF(Revenue!C40=0,0,Revenue!C52/Revenue!C40) -> 17880 | D24: =IF(Revenue!D40=0,0,Revenue!D52/Revenue!D40) -> 11280.533 | E24: =IF(Revenue!E40=0,0,Revenue!E52/Revenue!E40) -> 10350.682 | F24: =IF(Revenue!F40=0,0,Revenue!F52/Revenue!F40) -> 10640.597 | G24: =IF(Revenue!G40=0,0,Revenue!G52/Revenue!G40) -> 11563.767
A25: Effective take rate (rev / new listings $) | B25: % | C25: =IF(Revenue!C42=0,0,Revenue!C52/Revenue!C42) -> 0.2235 | D25: =IF(Revenue!D42=0,0,Revenue!D52/Revenue!D42) -> 0.15107857 | E25: =IF(Revenue!E42=0,0,Revenue!E52/Revenue!E42) -> 0.12835667 | F25: =IF(Revenue!F42=0,0,Revenue!F52/Revenue!F42) -> 0.12095586 | G25: =IF(Revenue!G42=0,0,Revenue!G52/Revenue!G42) -> 0.12447907
